{
 "cells": [
  {
   "cell_type": "markdown",
   "id": "53cd111d",
   "metadata": {},
   "source": [
    "### EfficientNetB0"
   ]
  },
  {
   "cell_type": "code",
   "execution_count": 1,
   "id": "40a0b273",
   "metadata": {},
   "outputs": [],
   "source": [
    "import numpy as np\n",
    "import tensorflow as tf\n",
    "from tensorflow.keras import layers, models\n",
    "from tensorflow.keras.applications import EfficientNetB0\n",
    "from tensorflow.keras.preprocessing.image import ImageDataGenerator"
   ]
  },
  {
   "cell_type": "code",
   "execution_count": 2,
   "id": "6a232777",
   "metadata": {},
   "outputs": [],
   "source": [
    "Xtrain = np.load('Xtrain.npz')\n",
    "Xtrain = Xtrain['x']\n",
    "Ytrain = np.load('Ytrain.npz')\n",
    "Ytrain = Ytrain['y']"
   ]
  },
  {
   "cell_type": "code",
   "execution_count": 3,
   "id": "31001803",
   "metadata": {},
   "outputs": [],
   "source": [
    "Xtest = np.load('Xtest.npz')\n",
    "Xtest = Xtest['x']\n",
    "Ytest = np.load('Ytest.npz')\n",
    "Ytest = Ytest['y']"
   ]
  },
  {
   "cell_type": "code",
   "execution_count": 4,
   "id": "e0e22b20",
   "metadata": {},
   "outputs": [],
   "source": [
    "Xval = np.load('Xval.npz')\n",
    "Xval = Xval['x']\n",
    "Yval = np.load('Yval.npz')\n",
    "Yval = Yval['y']"
   ]
  },
  {
   "cell_type": "code",
   "execution_count": 5,
   "id": "d482d2c5",
   "metadata": {},
   "outputs": [],
   "source": [
    "base_model = EfficientNetB0(weights='imagenet', include_top=False, input_shape=(Xtrain.shape[1], Xtrain.shape[2], 3))"
   ]
  },
  {
   "cell_type": "code",
   "execution_count": 6,
   "id": "488fed60",
   "metadata": {},
   "outputs": [],
   "source": [
    "Xtrain = np.expand_dims(Xtrain, axis=-1) \n",
    "Xtrain = np.repeat(Xtrain, 3, axis=-1)"
   ]
  },
  {
   "cell_type": "code",
   "execution_count": 7,
   "id": "b2a16351",
   "metadata": {},
   "outputs": [],
   "source": [
    "Xval = np.expand_dims(Xval, axis=-1)\n",
    "Xval = np.repeat(Xval, 3, axis=-1)"
   ]
  },
  {
   "cell_type": "code",
   "execution_count": 15,
   "id": "6ef9bd59",
   "metadata": {},
   "outputs": [],
   "source": [
    "Xtest = np.expand_dims(Xval, axis=-1)\n",
    "Xtest = np.repeat(Xval, 3, axis=-1)"
   ]
  },
  {
   "cell_type": "code",
   "execution_count": 8,
   "id": "10cb7d98",
   "metadata": {},
   "outputs": [],
   "source": [
    "base_model.trainable = False"
   ]
  },
  {
   "cell_type": "code",
   "execution_count": 9,
   "id": "55b20d94",
   "metadata": {},
   "outputs": [],
   "source": [
    "model = models.Sequential([\n",
    "    base_model,\n",
    "    layers.GlobalAveragePooling2D(),\n",
    "    layers.Dense(128, activation='relu'),\n",
    "    layers.Dense(5, activation='softmax')  # Assuming num_classes is the number of classes you want to classify\n",
    "])"
   ]
  },
  {
   "cell_type": "code",
   "execution_count": 10,
   "id": "69d06608",
   "metadata": {},
   "outputs": [],
   "source": [
    "model.compile(optimizer='adam',\n",
    "              loss='sparse_categorical_crossentropy',\n",
    "              metrics=['accuracy'])"
   ]
  },
  {
   "cell_type": "code",
   "execution_count": 11,
   "id": "1df09819",
   "metadata": {},
   "outputs": [],
   "source": [
    "train_datagen = ImageDataGenerator(rescale=1./255,\n",
    "                                  rotation_range=20,\n",
    "                                  width_shift_range=0.2,\n",
    "                                  height_shift_range=0.2,\n",
    "                                  shear_range=0.2,\n",
    "                                  zoom_range=0.2,\n",
    "                                  horizontal_flip=True,\n",
    "                                  fill_mode='nearest')"
   ]
  },
  {
   "cell_type": "code",
   "execution_count": 12,
   "id": "45b66c4a",
   "metadata": {},
   "outputs": [
    {
     "name": "stdout",
     "output_type": "stream",
     "text": [
      "Epoch 1/10\n",
      "92/92 [==============================] - 196s 2s/step - loss: 1.3269 - accuracy: 0.4700 - val_loss: 2.3860 - val_accuracy: 0.0546\n",
      "Epoch 2/10\n",
      "92/92 [==============================] - 182s 2s/step - loss: 1.2931 - accuracy: 0.4874 - val_loss: 2.4767 - val_accuracy: 0.0519\n",
      "Epoch 3/10\n",
      "92/92 [==============================] - 166s 2s/step - loss: 1.2915 - accuracy: 0.4877 - val_loss: 2.5216 - val_accuracy: 0.0574\n",
      "Epoch 4/10\n",
      "92/92 [==============================] - 152s 2s/step - loss: 1.2817 - accuracy: 0.4945 - val_loss: 2.4996 - val_accuracy: 0.0574\n",
      "Epoch 5/10\n",
      "92/92 [==============================] - 157s 2s/step - loss: 1.2865 - accuracy: 0.4922 - val_loss: 2.4879 - val_accuracy: 0.0574\n",
      "Epoch 6/10\n",
      "92/92 [==============================] - 156s 2s/step - loss: 1.2737 - accuracy: 0.4932 - val_loss: 2.5038 - val_accuracy: 0.0574\n",
      "Epoch 7/10\n",
      "92/92 [==============================] - 166s 2s/step - loss: 1.2764 - accuracy: 0.4939 - val_loss: 2.4757 - val_accuracy: 0.0601\n",
      "Epoch 8/10\n",
      "92/92 [==============================] - 175s 2s/step - loss: 1.2755 - accuracy: 0.5007 - val_loss: 2.4860 - val_accuracy: 0.0574\n",
      "Epoch 9/10\n",
      "92/92 [==============================] - 187s 2s/step - loss: 1.2749 - accuracy: 0.4904 - val_loss: 2.4897 - val_accuracy: 0.0601\n",
      "Epoch 10/10\n",
      "92/92 [==============================] - 177s 2s/step - loss: 1.2684 - accuracy: 0.4983 - val_loss: 2.5285 - val_accuracy: 0.0601\n"
     ]
    },
    {
     "data": {
      "text/plain": [
       "<keras.callbacks.History at 0x17e898623a0>"
      ]
     },
     "execution_count": 12,
     "metadata": {},
     "output_type": "execute_result"
    }
   ],
   "source": [
    "train_generator = train_datagen.flow(Xtrain, Ytrain, batch_size=32)\n",
    "validation_data = (Xval, Yval)\n",
    "model.fit(train_generator, epochs=10, validation_data=validation_data)"
   ]
  },
  {
   "cell_type": "code",
   "execution_count": 17,
   "id": "48ad3f69",
   "metadata": {},
   "outputs": [
    {
     "ename": "InvalidArgumentError",
     "evalue": "Graph execution error:\n\nDetected at node 'sequential/efficientnetb0/normalization/sub' defined at (most recent call last):\n    File \"C:\\python-3.9.7\\lib\\runpy.py\", line 197, in _run_module_as_main\n      return _run_code(code, main_globals, None,\n    File \"C:\\python-3.9.7\\lib\\runpy.py\", line 87, in _run_code\n      exec(code, run_globals)\n    File \"C:\\python-3.9.7\\lib\\site-packages\\ipykernel_launcher.py\", line 17, in <module>\n      app.launch_new_instance()\n    File \"C:\\python-3.9.7\\lib\\site-packages\\traitlets\\config\\application.py\", line 846, in launch_instance\n      app.start()\n    File \"C:\\python-3.9.7\\lib\\site-packages\\ipykernel\\kernelapp.py\", line 712, in start\n      self.io_loop.start()\n    File \"C:\\python-3.9.7\\lib\\site-packages\\tornado\\platform\\asyncio.py\", line 199, in start\n      self.asyncio_loop.run_forever()\n    File \"C:\\python-3.9.7\\lib\\asyncio\\base_events.py\", line 596, in run_forever\n      self._run_once()\n    File \"C:\\python-3.9.7\\lib\\asyncio\\base_events.py\", line 1890, in _run_once\n      handle._run()\n    File \"C:\\python-3.9.7\\lib\\asyncio\\events.py\", line 80, in _run\n      self._context.run(self._callback, *self._args)\n    File \"C:\\python-3.9.7\\lib\\site-packages\\ipykernel\\kernelbase.py\", line 504, in dispatch_queue\n      await self.process_one()\n    File \"C:\\python-3.9.7\\lib\\site-packages\\ipykernel\\kernelbase.py\", line 493, in process_one\n      await dispatch(*args)\n    File \"C:\\python-3.9.7\\lib\\site-packages\\ipykernel\\kernelbase.py\", line 400, in dispatch_shell\n      await result\n    File \"C:\\python-3.9.7\\lib\\site-packages\\ipykernel\\kernelbase.py\", line 724, in execute_request\n      reply_content = await reply_content\n    File \"C:\\python-3.9.7\\lib\\site-packages\\ipykernel\\ipkernel.py\", line 390, in do_execute\n      res = shell.run_cell(code, store_history=store_history, silent=silent)\n    File \"C:\\python-3.9.7\\lib\\site-packages\\ipykernel\\zmqshell.py\", line 528, in run_cell\n      return super().run_cell(*args, **kwargs)\n    File \"C:\\python-3.9.7\\lib\\site-packages\\IPython\\core\\interactiveshell.py\", line 2863, in run_cell\n      result = self._run_cell(\n    File \"C:\\python-3.9.7\\lib\\site-packages\\IPython\\core\\interactiveshell.py\", line 2909, in _run_cell\n      return runner(coro)\n    File \"C:\\python-3.9.7\\lib\\site-packages\\IPython\\core\\async_helpers.py\", line 129, in _pseudo_sync_runner\n      coro.send(None)\n    File \"C:\\python-3.9.7\\lib\\site-packages\\IPython\\core\\interactiveshell.py\", line 3106, in run_cell_async\n      has_raised = await self.run_ast_nodes(code_ast.body, cell_name,\n    File \"C:\\python-3.9.7\\lib\\site-packages\\IPython\\core\\interactiveshell.py\", line 3309, in run_ast_nodes\n      if await self.run_code(code, result, async_=asy):\n    File \"C:\\python-3.9.7\\lib\\site-packages\\IPython\\core\\interactiveshell.py\", line 3369, in run_code\n      exec(code_obj, self.user_global_ns, self.user_ns)\n    File \"C:\\Users\\Vaibhavi\\AppData\\Local\\Temp\\ipykernel_4328\\1290658050.py\", line 1, in <cell line: 1>\n      test_loss, test_acc = model.evaluate(Xtest, Ytest)\n    File \"C:\\python-3.9.7\\lib\\site-packages\\keras\\utils\\traceback_utils.py\", line 65, in error_handler\n      return fn(*args, **kwargs)\n    File \"C:\\python-3.9.7\\lib\\site-packages\\keras\\engine\\training.py\", line 2040, in evaluate\n      tmp_logs = self.test_function(iterator)\n    File \"C:\\python-3.9.7\\lib\\site-packages\\keras\\engine\\training.py\", line 1820, in test_function\n      return step_function(self, iterator)\n    File \"C:\\python-3.9.7\\lib\\site-packages\\keras\\engine\\training.py\", line 1804, in step_function\n      outputs = model.distribute_strategy.run(run_step, args=(data,))\n    File \"C:\\python-3.9.7\\lib\\site-packages\\keras\\engine\\training.py\", line 1792, in run_step\n      outputs = model.test_step(data)\n    File \"C:\\python-3.9.7\\lib\\site-packages\\keras\\engine\\training.py\", line 1756, in test_step\n      y_pred = self(x, training=False)\n    File \"C:\\python-3.9.7\\lib\\site-packages\\keras\\utils\\traceback_utils.py\", line 65, in error_handler\n      return fn(*args, **kwargs)\n    File \"C:\\python-3.9.7\\lib\\site-packages\\keras\\engine\\training.py\", line 561, in __call__\n      return super().__call__(*args, **kwargs)\n    File \"C:\\python-3.9.7\\lib\\site-packages\\keras\\utils\\traceback_utils.py\", line 65, in error_handler\n      return fn(*args, **kwargs)\n    File \"C:\\python-3.9.7\\lib\\site-packages\\keras\\engine\\base_layer.py\", line 1132, in __call__\n      outputs = call_fn(inputs, *args, **kwargs)\n    File \"C:\\python-3.9.7\\lib\\site-packages\\keras\\utils\\traceback_utils.py\", line 96, in error_handler\n      return fn(*args, **kwargs)\n    File \"C:\\python-3.9.7\\lib\\site-packages\\keras\\engine\\sequential.py\", line 413, in call\n      return super().call(inputs, training=training, mask=mask)\n    File \"C:\\python-3.9.7\\lib\\site-packages\\keras\\engine\\functional.py\", line 511, in call\n      return self._run_internal_graph(inputs, training=training, mask=mask)\n    File \"C:\\python-3.9.7\\lib\\site-packages\\keras\\engine\\functional.py\", line 668, in _run_internal_graph\n      outputs = node.layer(*args, **kwargs)\n    File \"C:\\python-3.9.7\\lib\\site-packages\\keras\\utils\\traceback_utils.py\", line 65, in error_handler\n      return fn(*args, **kwargs)\n    File \"C:\\python-3.9.7\\lib\\site-packages\\keras\\engine\\training.py\", line 561, in __call__\n      return super().__call__(*args, **kwargs)\n    File \"C:\\python-3.9.7\\lib\\site-packages\\keras\\utils\\traceback_utils.py\", line 65, in error_handler\n      return fn(*args, **kwargs)\n    File \"C:\\python-3.9.7\\lib\\site-packages\\keras\\engine\\base_layer.py\", line 1132, in __call__\n      outputs = call_fn(inputs, *args, **kwargs)\n    File \"C:\\python-3.9.7\\lib\\site-packages\\keras\\utils\\traceback_utils.py\", line 96, in error_handler\n      return fn(*args, **kwargs)\n    File \"C:\\python-3.9.7\\lib\\site-packages\\keras\\engine\\functional.py\", line 511, in call\n      return self._run_internal_graph(inputs, training=training, mask=mask)\n    File \"C:\\python-3.9.7\\lib\\site-packages\\keras\\engine\\functional.py\", line 668, in _run_internal_graph\n      outputs = node.layer(*args, **kwargs)\n    File \"C:\\python-3.9.7\\lib\\site-packages\\keras\\utils\\traceback_utils.py\", line 65, in error_handler\n      return fn(*args, **kwargs)\n    File \"C:\\python-3.9.7\\lib\\site-packages\\keras\\engine\\base_layer.py\", line 1132, in __call__\n      outputs = call_fn(inputs, *args, **kwargs)\n    File \"C:\\python-3.9.7\\lib\\site-packages\\keras\\utils\\traceback_utils.py\", line 96, in error_handler\n      return fn(*args, **kwargs)\n    File \"C:\\python-3.9.7\\lib\\site-packages\\keras\\layers\\preprocessing\\normalization.py\", line 361, in call\n      return (inputs - self.mean) / tf.maximum(\nNode: 'sequential/efficientnetb0/normalization/sub'\nIncompatible shapes: [32,255,255,9] vs. [1,1,1,3]\n\t [[{{node sequential/efficientnetb0/normalization/sub}}]] [Op:__inference_test_function_23765]",
     "output_type": "error",
     "traceback": [
      "\u001b[1;31m---------------------------------------------------------------------------\u001b[0m",
      "\u001b[1;31mInvalidArgumentError\u001b[0m                      Traceback (most recent call last)",
      "Input \u001b[1;32mIn [17]\u001b[0m, in \u001b[0;36m<cell line: 1>\u001b[1;34m()\u001b[0m\n\u001b[1;32m----> 1\u001b[0m test_loss, test_acc \u001b[38;5;241m=\u001b[39m \u001b[43mmodel\u001b[49m\u001b[38;5;241;43m.\u001b[39;49m\u001b[43mevaluate\u001b[49m\u001b[43m(\u001b[49m\u001b[43mXtest\u001b[49m\u001b[43m,\u001b[49m\u001b[43m \u001b[49m\u001b[43mYtest\u001b[49m\u001b[43m)\u001b[49m\n\u001b[0;32m      2\u001b[0m \u001b[38;5;28mprint\u001b[39m(\u001b[38;5;124m'\u001b[39m\u001b[38;5;124mTest accuracy:\u001b[39m\u001b[38;5;124m'\u001b[39m, test_acc)\n",
      "File \u001b[1;32mC:\\python-3.9.7\\lib\\site-packages\\keras\\utils\\traceback_utils.py:70\u001b[0m, in \u001b[0;36mfilter_traceback.<locals>.error_handler\u001b[1;34m(*args, **kwargs)\u001b[0m\n\u001b[0;32m     67\u001b[0m     filtered_tb \u001b[38;5;241m=\u001b[39m _process_traceback_frames(e\u001b[38;5;241m.\u001b[39m__traceback__)\n\u001b[0;32m     68\u001b[0m     \u001b[38;5;66;03m# To get the full stack trace, call:\u001b[39;00m\n\u001b[0;32m     69\u001b[0m     \u001b[38;5;66;03m# `tf.debugging.disable_traceback_filtering()`\u001b[39;00m\n\u001b[1;32m---> 70\u001b[0m     \u001b[38;5;28;01mraise\u001b[39;00m e\u001b[38;5;241m.\u001b[39mwith_traceback(filtered_tb) \u001b[38;5;28;01mfrom\u001b[39;00m \u001b[38;5;28mNone\u001b[39m\n\u001b[0;32m     71\u001b[0m \u001b[38;5;28;01mfinally\u001b[39;00m:\n\u001b[0;32m     72\u001b[0m     \u001b[38;5;28;01mdel\u001b[39;00m filtered_tb\n",
      "File \u001b[1;32mC:\\python-3.9.7\\lib\\site-packages\\tensorflow\\python\\eager\\execute.py:52\u001b[0m, in \u001b[0;36mquick_execute\u001b[1;34m(op_name, num_outputs, inputs, attrs, ctx, name)\u001b[0m\n\u001b[0;32m     50\u001b[0m \u001b[38;5;28;01mtry\u001b[39;00m:\n\u001b[0;32m     51\u001b[0m   ctx\u001b[38;5;241m.\u001b[39mensure_initialized()\n\u001b[1;32m---> 52\u001b[0m   tensors \u001b[38;5;241m=\u001b[39m pywrap_tfe\u001b[38;5;241m.\u001b[39mTFE_Py_Execute(ctx\u001b[38;5;241m.\u001b[39m_handle, device_name, op_name,\n\u001b[0;32m     53\u001b[0m                                       inputs, attrs, num_outputs)\n\u001b[0;32m     54\u001b[0m \u001b[38;5;28;01mexcept\u001b[39;00m core\u001b[38;5;241m.\u001b[39m_NotOkStatusException \u001b[38;5;28;01mas\u001b[39;00m e:\n\u001b[0;32m     55\u001b[0m   \u001b[38;5;28;01mif\u001b[39;00m name \u001b[38;5;129;01mis\u001b[39;00m \u001b[38;5;129;01mnot\u001b[39;00m \u001b[38;5;28;01mNone\u001b[39;00m:\n",
      "\u001b[1;31mInvalidArgumentError\u001b[0m: Graph execution error:\n\nDetected at node 'sequential/efficientnetb0/normalization/sub' defined at (most recent call last):\n    File \"C:\\python-3.9.7\\lib\\runpy.py\", line 197, in _run_module_as_main\n      return _run_code(code, main_globals, None,\n    File \"C:\\python-3.9.7\\lib\\runpy.py\", line 87, in _run_code\n      exec(code, run_globals)\n    File \"C:\\python-3.9.7\\lib\\site-packages\\ipykernel_launcher.py\", line 17, in <module>\n      app.launch_new_instance()\n    File \"C:\\python-3.9.7\\lib\\site-packages\\traitlets\\config\\application.py\", line 846, in launch_instance\n      app.start()\n    File \"C:\\python-3.9.7\\lib\\site-packages\\ipykernel\\kernelapp.py\", line 712, in start\n      self.io_loop.start()\n    File \"C:\\python-3.9.7\\lib\\site-packages\\tornado\\platform\\asyncio.py\", line 199, in start\n      self.asyncio_loop.run_forever()\n    File \"C:\\python-3.9.7\\lib\\asyncio\\base_events.py\", line 596, in run_forever\n      self._run_once()\n    File \"C:\\python-3.9.7\\lib\\asyncio\\base_events.py\", line 1890, in _run_once\n      handle._run()\n    File \"C:\\python-3.9.7\\lib\\asyncio\\events.py\", line 80, in _run\n      self._context.run(self._callback, *self._args)\n    File \"C:\\python-3.9.7\\lib\\site-packages\\ipykernel\\kernelbase.py\", line 504, in dispatch_queue\n      await self.process_one()\n    File \"C:\\python-3.9.7\\lib\\site-packages\\ipykernel\\kernelbase.py\", line 493, in process_one\n      await dispatch(*args)\n    File \"C:\\python-3.9.7\\lib\\site-packages\\ipykernel\\kernelbase.py\", line 400, in dispatch_shell\n      await result\n    File \"C:\\python-3.9.7\\lib\\site-packages\\ipykernel\\kernelbase.py\", line 724, in execute_request\n      reply_content = await reply_content\n    File \"C:\\python-3.9.7\\lib\\site-packages\\ipykernel\\ipkernel.py\", line 390, in do_execute\n      res = shell.run_cell(code, store_history=store_history, silent=silent)\n    File \"C:\\python-3.9.7\\lib\\site-packages\\ipykernel\\zmqshell.py\", line 528, in run_cell\n      return super().run_cell(*args, **kwargs)\n    File \"C:\\python-3.9.7\\lib\\site-packages\\IPython\\core\\interactiveshell.py\", line 2863, in run_cell\n      result = self._run_cell(\n    File \"C:\\python-3.9.7\\lib\\site-packages\\IPython\\core\\interactiveshell.py\", line 2909, in _run_cell\n      return runner(coro)\n    File \"C:\\python-3.9.7\\lib\\site-packages\\IPython\\core\\async_helpers.py\", line 129, in _pseudo_sync_runner\n      coro.send(None)\n    File \"C:\\python-3.9.7\\lib\\site-packages\\IPython\\core\\interactiveshell.py\", line 3106, in run_cell_async\n      has_raised = await self.run_ast_nodes(code_ast.body, cell_name,\n    File \"C:\\python-3.9.7\\lib\\site-packages\\IPython\\core\\interactiveshell.py\", line 3309, in run_ast_nodes\n      if await self.run_code(code, result, async_=asy):\n    File \"C:\\python-3.9.7\\lib\\site-packages\\IPython\\core\\interactiveshell.py\", line 3369, in run_code\n      exec(code_obj, self.user_global_ns, self.user_ns)\n    File \"C:\\Users\\Vaibhavi\\AppData\\Local\\Temp\\ipykernel_4328\\1290658050.py\", line 1, in <cell line: 1>\n      test_loss, test_acc = model.evaluate(Xtest, Ytest)\n    File \"C:\\python-3.9.7\\lib\\site-packages\\keras\\utils\\traceback_utils.py\", line 65, in error_handler\n      return fn(*args, **kwargs)\n    File \"C:\\python-3.9.7\\lib\\site-packages\\keras\\engine\\training.py\", line 2040, in evaluate\n      tmp_logs = self.test_function(iterator)\n    File \"C:\\python-3.9.7\\lib\\site-packages\\keras\\engine\\training.py\", line 1820, in test_function\n      return step_function(self, iterator)\n    File \"C:\\python-3.9.7\\lib\\site-packages\\keras\\engine\\training.py\", line 1804, in step_function\n      outputs = model.distribute_strategy.run(run_step, args=(data,))\n    File \"C:\\python-3.9.7\\lib\\site-packages\\keras\\engine\\training.py\", line 1792, in run_step\n      outputs = model.test_step(data)\n    File \"C:\\python-3.9.7\\lib\\site-packages\\keras\\engine\\training.py\", line 1756, in test_step\n      y_pred = self(x, training=False)\n    File \"C:\\python-3.9.7\\lib\\site-packages\\keras\\utils\\traceback_utils.py\", line 65, in error_handler\n      return fn(*args, **kwargs)\n    File \"C:\\python-3.9.7\\lib\\site-packages\\keras\\engine\\training.py\", line 561, in __call__\n      return super().__call__(*args, **kwargs)\n    File \"C:\\python-3.9.7\\lib\\site-packages\\keras\\utils\\traceback_utils.py\", line 65, in error_handler\n      return fn(*args, **kwargs)\n    File \"C:\\python-3.9.7\\lib\\site-packages\\keras\\engine\\base_layer.py\", line 1132, in __call__\n      outputs = call_fn(inputs, *args, **kwargs)\n    File \"C:\\python-3.9.7\\lib\\site-packages\\keras\\utils\\traceback_utils.py\", line 96, in error_handler\n      return fn(*args, **kwargs)\n    File \"C:\\python-3.9.7\\lib\\site-packages\\keras\\engine\\sequential.py\", line 413, in call\n      return super().call(inputs, training=training, mask=mask)\n    File \"C:\\python-3.9.7\\lib\\site-packages\\keras\\engine\\functional.py\", line 511, in call\n      return self._run_internal_graph(inputs, training=training, mask=mask)\n    File \"C:\\python-3.9.7\\lib\\site-packages\\keras\\engine\\functional.py\", line 668, in _run_internal_graph\n      outputs = node.layer(*args, **kwargs)\n    File \"C:\\python-3.9.7\\lib\\site-packages\\keras\\utils\\traceback_utils.py\", line 65, in error_handler\n      return fn(*args, **kwargs)\n    File \"C:\\python-3.9.7\\lib\\site-packages\\keras\\engine\\training.py\", line 561, in __call__\n      return super().__call__(*args, **kwargs)\n    File \"C:\\python-3.9.7\\lib\\site-packages\\keras\\utils\\traceback_utils.py\", line 65, in error_handler\n      return fn(*args, **kwargs)\n    File \"C:\\python-3.9.7\\lib\\site-packages\\keras\\engine\\base_layer.py\", line 1132, in __call__\n      outputs = call_fn(inputs, *args, **kwargs)\n    File \"C:\\python-3.9.7\\lib\\site-packages\\keras\\utils\\traceback_utils.py\", line 96, in error_handler\n      return fn(*args, **kwargs)\n    File \"C:\\python-3.9.7\\lib\\site-packages\\keras\\engine\\functional.py\", line 511, in call\n      return self._run_internal_graph(inputs, training=training, mask=mask)\n    File \"C:\\python-3.9.7\\lib\\site-packages\\keras\\engine\\functional.py\", line 668, in _run_internal_graph\n      outputs = node.layer(*args, **kwargs)\n    File \"C:\\python-3.9.7\\lib\\site-packages\\keras\\utils\\traceback_utils.py\", line 65, in error_handler\n      return fn(*args, **kwargs)\n    File \"C:\\python-3.9.7\\lib\\site-packages\\keras\\engine\\base_layer.py\", line 1132, in __call__\n      outputs = call_fn(inputs, *args, **kwargs)\n    File \"C:\\python-3.9.7\\lib\\site-packages\\keras\\utils\\traceback_utils.py\", line 96, in error_handler\n      return fn(*args, **kwargs)\n    File \"C:\\python-3.9.7\\lib\\site-packages\\keras\\layers\\preprocessing\\normalization.py\", line 361, in call\n      return (inputs - self.mean) / tf.maximum(\nNode: 'sequential/efficientnetb0/normalization/sub'\nIncompatible shapes: [32,255,255,9] vs. [1,1,1,3]\n\t [[{{node sequential/efficientnetb0/normalization/sub}}]] [Op:__inference_test_function_23765]"
     ]
    }
   ],
   "source": [
    "test_loss, test_acc = model.evaluate(Xtest, Ytest)\n",
    "print('Test accuracy:', test_acc)"
   ]
  },
  {
   "cell_type": "code",
   "execution_count": null,
   "id": "2e5f4ca1",
   "metadata": {},
   "outputs": [],
   "source": []
  }
 ],
 "metadata": {
  "kernelspec": {
   "display_name": "Python 3 (ipykernel)",
   "language": "python",
   "name": "python3"
  },
  "language_info": {
   "codemirror_mode": {
    "name": "ipython",
    "version": 3
   },
   "file_extension": ".py",
   "mimetype": "text/x-python",
   "name": "python",
   "nbconvert_exporter": "python",
   "pygments_lexer": "ipython3",
   "version": "3.9.7"
  }
 },
 "nbformat": 4,
 "nbformat_minor": 5
}
